<?xml version='1.0'?>
<sdf version="1.9">
<model name="digit_left_leg">
<link name="left_hip_roll">
    <pose>0 0 0 0 0 0 </pose>
    <inertial>
        <pose>-0.001967 0.000244 0.031435 0 0 0</pose>
        <mass>0.915088</mass>
        <inertia>
        <ixx>0.001017</ixx>
        <iyy>0.001148</iyy>
        <izz>0.000766</izz>
        <ixy>-3e-06</ixy>
        <ixz>1.3e-05</ixz>
        <iyz>-4e-06</iyz>
        </inertia>
    </inertial>
    <visual name="left_hip_roll_visual">
        <pose>0 0 0 0 0 0</pose>
        <geometry>
        <mesh> 
            <uri>package://digit_sdf_model/visual/hip-yaw-housing.obj</uri> 
        </mesh>
        </geometry>
    </visual>
</link>
<link name="left_hip_yaw">
    <pose>0 0 0 0 0 0 </pose>
    <inertial>
        <pose>1e-05 -0.001945 0.042033 0 0 0</pose>
        <mass>0.818753</mass>
        <inertia>
        <ixx>0.001627</ixx>
        <iyy>0.001929</iyy>
        <izz>0.00077</izz>
        <ixy>-1e-06</ixy>
        <ixz>2e-06</ixz>
        <iyz>5.3e-05</iyz>
        </inertia>
    </inertial>
    <visual name="left_hip_yaw_visual">
        <pose relative_to="left_hip_yaw_joint">0 0 0 0 0 0</pose>
        <geometry>
        <mesh>
            <uri>package://digit_sdf_model/visual/hip-pitch-housing.obj</uri> 
        </mesh>
        </geometry>
    </visual>
</link>
<link name="left_hip_pitch">
    <pose relative_to="left_hip_pitch_joint">0 0 0 0 0 0</pose>
    <inertial>
        <pose>0.060537 0.000521 -0.038857 0 0 0</pose>
        <mass>6.244279</mass>
        <inertia>
        <ixx>0.011533</ixx>
        <iyy>0.033345</iyy>
        <izz>0.033958</izz>
        <ixy>-0.000171</ixy>
        <ixz>0.000148</ixz>
        <iyz>0.000178</iyz>
        </inertia>
    </inertial>
    <visual name="left_hip_pitch_visual">
        <pose relative_to="left_hip_pitch_joint">0 0 0 0 0 0</pose>
        <geometry>
        <mesh> 
            <uri>package://digit_sdf_model/visual/hip-pitch.obj</uri> 
        </mesh>
        </geometry>
    </visual>
    <collision name="left_hip_geom_1">
        <pose relative_to="left_hip_pitch_joint">0 0 -0.044 0 0 0</pose>
        <geometry>
            <cylinder>
                <radius>0.05</radius>
                <length>0.072</length>
            </cylinder>
        </geometry>
    </collision>
    <collision name="left_hip_geom_2">
        <pose relative_to="left_hip_pitch_joint">0.12 0 -0.04 0 0 0</pose>
        <geometry>
            <cylinder>
                <radius>0.05</radius>
                <length>0.072</length>
            </cylinder>
        </geometry>
    </collision>
    <collision name="left_hip_geom_3">
        <pose relative_to="left_hip_pitch_joint">0.06 0 -0.04 0 0 0</pose>
        <geometry>
            <box>
                <size>0.06 0.05 0.072</size>
            </box>
        </geometry>
    </collision>
</link>
<link name="left_knee">
    <pose relative_to="left_knee_joint">0 0 0 0 -1.57 0</pose>
    <inertial>
        <pose>0.045641 0.042154 0.001657 0 0 0</pose>
        <mass>1.227077</mass>
        <inertia>
        <ixx>0.002643</ixx>
        <iyy>0.005098</iyy>
        <izz>0.007019</izz>
        <ixy>-0.001832</ixy>
        <ixz>6.6e-05</ixz>
        <iyz>4.5e-05</iyz>
        </inertia>
    </inertial>
    <visual name="left_knee_visual">
        <pose relative_to="left_knee_joint">0 0 0 0 0 0</pose>
        <geometry>
        <mesh> 
            <uri>package://digit_sdf_model/visual/knee.obj</uri> 
        </mesh>
        </geometry>
    </visual>
</link>
<link name="left_shin">
    <pose relative_to="left_knee_to_shin_joint">0 0 0 0 -1.57 0</pose>
    <inertial>
        <pose>0.174265 0.010265 0.00107 0 0 0</pose>
        <mass>0.895793</mass>
        <inertia>
        <ixx>0.001128</ixx>
        <iyy>0.022492</iyy>
        <izz>0.022793</izz>
        <ixy> 0.001098</ixy>
        <ixz>0.000196</ixz>
        <iyz>-3e-06</iyz>
        </inertia>
    </inertial>
    <visual name="left_shin_visual">
        <pose relative_to="left_knee_to_shin_joint">0 0 0 0 0 0</pose>
        <geometry>
        <mesh> 
            <uri>package://digit_sdf_model/visual/shin.obj</uri> 
        </mesh>
        </geometry>
    </visual>
    <collision name="left_shin_geom_1">
        <pose relative_to="left_knee_to_shin_joint">0.23 0 0 0 1.5708 0</pose>
        <geometry>
            <cylinder>
                <radius>0.03</radius>
                <length>0.1715</length>
            </cylinder>
        </geometry>
    </collision>
    <collision name="left_shin_geom_2">
        <pose relative_to="left_knee_to_shin_joint">0.125 0.009 0 1.5708 1.466 0</pose>
        <geometry>
            <cylinder>
                <radius>0.05</radius>
                <length>0.1</length>
            </cylinder>
        </geometry>
    </collision>
</link>
<link name="left_tarsus">
    <pose relative_to="left_shin_to_tarsus_joint">0 0 0 0 -1.57 0</pose>
    <inertial>
        <pose>0.100777 -0.029183 0.000678 0 0 0</pose>
        <mass>1.322865</mass>
        <inertia>
        <ixx>0.000932</ixx>
        <iyy>0.016409</iyy>
        <izz>0.016501</izz>
        <ixy>0.00061</ixy>
        <ixz>0.000102</ixz>
        <iyz>9e-06</iyz>
        </inertia>
    </inertial>
    <visual name="left_tarsus_visual">
        <pose relative_to="left_shin_to_tarsus_joint">0 0 0 0 0 0</pose>
        <geometry>
        <mesh> 
            <uri>package://digit_sdf_model/visual/tarsus.obj</uri> 
        </mesh>
        </geometry>
    </visual>
    <collision name="left_tarsus_geom_1">
        <pose relative_to="left_shin_to_tarsus_joint">0.21 -0.03 0 0 1.5708 0</pose>
        <geometry>
            <capsule>
                <radius>0.02</radius>
                <length>0.18</length>
            </capsule>
        </geometry>
    </collision>
    <collision name="left_tarsus_geom_2">
        <pose relative_to="left_shin_to_tarsus_joint">-0.07 -0.012 0 0.0873 0 1.13446</pose>
        <geometry>
            <box>
                <size>0.007 0.07 0.03</size>
            </box>
        </geometry>
    </collision>
</link>
<link name="left_toe_pitch">
    <pose relative_to="left_toe_pitch_joint">0 0 0 0 -1.57 0</pose>
    <inertial>
        <pose>-0.000141 2e-06 3e-06 0 0 0</pose>
        <mass>0.043881</mass>
        <inertia>
        <ixx>5e-06</ixx>
        <iyy>8e-06</iyy>
        <izz>4e-06</izz>
        <ixy>0</ixy>
        <ixz>0</ixz>
        <iyz>0</iyz>
        </inertia>
    </inertial>
    <visual name="left_toe_pitch_visual">
        <pose relative_to="left_toe_pitch_joint">0 0 0 0 0 0</pose>
        <geometry>
        <mesh> 
            <uri>package://digit_sdf_model/visual/toe-pitch.obj</uri> 
        </mesh>
        </geometry>
    </visual>
</link>
<link name="left_toe_roll">
    <pose relative_to="left_toe_roll_joint">0 0 0 0 -1.57 0</pose>
    <inertial>
        <pose>9e-06 -0.028084 -0.023204 0 0 0</pose>
        <mass>0.531283</mass>
        <inertia>
        <ixx>0.00187</ixx>
        <iyy>0.001616</iyy>
        <izz>0.000843</izz>
        <ixy>0</ixy>
        <ixz>0</ixz>
        <iyz>0.000566</iyz>
        </inertia>
    </inertial>
    <visual name="left_toe_roll_visual">
        <pose relative_to="left_toe_roll_joint">0 0 0 0 0 0</pose>
        <geometry>
        <mesh> 
            <uri>package://digit_sdf_model/visual/toe-roll.obj</uri> 
        </mesh>
        </geometry>
    </visual>
    <collision name="left_toe_geom_1">
        <pose relative_to="left_toe_roll_joint">0 -0.0437 -0.0255 -1.0472 0 0</pose>
        <geometry>
            <box>
                <size>0.04 0.1175 0.0115</size>
            </box>
        </geometry>
    </collision>
</link>
<joint name="left_hip_yaw_joint" type="continuous">
    <pose>-0.0505 0 0.044 0 -1.57 0</pose>
    <axis>
        <xyz>0 0 1</xyz> 
        <limit> 
            <lower>-0.698132</lower>
            <upper>0.698132</upper>
            <effort>1.4</effort>
            <velocity>10</velocity>
        </limit>
    </axis>
    <parent>left_hip_roll</parent>
    <child>left_hip_yaw</child>
</joint>
<joint name="left_hip_pitch_joint" type="continuous">
    <pose relative_to="left_hip_yaw_joint">0 0.004 0.068 -1.57079632679 -0.785398163397 3.14159265359</pose>
    <axis>
        <xyz>0 0 -1</xyz>
        <limit> 
            <lower>-1.0472</lower>
            <upper>1.5708</upper>
            <effort>12.5</effort>
            <velocity>10</velocity>
        </limit>
    </axis>
    <parent>left_hip_yaw</parent>
    <child>left_hip_pitch</child>
</joint>
<joint name="left_knee_joint" type="continuous">
    <pose relative_to="left_hip_pitch_joint">0.12 0 0.0045 0 0 -1.57079632679</pose>
    <axis>
        <xyz>0 0 1</xyz>
        <limit> 
            <lower>-1.39626</lower>
            <upper>1.019272</upper>
            <effort>1.4</effort>
            <velocity>10</velocity>
        </limit>
    </axis>
    <parent>left_hip_pitch</parent>
    <child>left_knee</child>
</joint>
<joint name="left_knee_to_shin_joint" type="fixed">
    <pose relative_to="left_knee_joint">0.060677 0.047406 0 0 0 0</pose>
    <axis>
        <xyz>0 0 1</xyz>
        <limit> 
            <lower>-0.35</lower>
            <upper>0.35</upper>
            <effort>0</effort>
            <velocity>10</velocity>
        </limit>
        <dynamics>
            <damping>0.1</damping>
        </dynamics>
    </axis>
    <parent>left_knee</parent>
    <child>left_shin</child>
</joint>
<joint name="left_shin_to_tarsus_joint" type="continuous">
    <pose relative_to="left_knee_to_shin_joint">0.434759 0.02 0 0 0 1.79769</pose>
    <axis>
        <xyz>0 0 1</xyz>
        <limit> 
            <lower>-1.2497</lower>
            <upper>0.8779</upper>
            <effort>0</effort>
            <velocity>20</velocity>
        </limit>
    </axis>
    <parent>left_shin</parent>
    <child>left_tarsus</child>
</joint>
<joint name="left_toe_pitch_joint" type="continuous">
    <pose relative_to="left_shin_to_tarsus_joint">0.408 -0.04 0 0 0 1.1956</pose>
    <axis>
        <xyz>0 0 1</xyz>
        <limit> 
            <lower>-0.785398163397</lower>
            <upper>0.785398163397</upper>
            <effort>0.9</effort>
            <velocity>11.5</velocity>
        </limit>
    </axis>
    <parent>left_tarsus</parent>
    <child>left_toe_pitch</child>
</joint>
<joint name="left_toe_roll_joint" type="continuous">
    <pose relative_to="left_toe_pitch_joint">0 0 0 0 1.5708 0</pose>
    <axis>
        <xyz>0 0 1</xyz>
        <limit> 
            <lower>-0.6109</lower>
            <upper>0.6109</upper>
            <effort>0.9</effort>
            <velocity>11.5</velocity>
        </limit>
    </axis>
    <parent>left_toe_pitch</parent>
    <child>left_toe_roll</child>
</joint>
</model>
</sdf>