<?xml version='1.0'?>
<sdf version="1.9">
<model name="digit_right_leg">
<link name="right_hip_roll">
    <pose>0 0 0 0 0 0</pose>
    <inertial>
        <pose>-0.001967 -0.000244 0.031435 0 0 0</pose>
        <mass>0.915088</mass>
        <inertia>
        <ixx>0.001017</ixx>
        <iyy>0.001148</iyy>
        <izz>0.000766</izz>
        <ixy>3e-06</ixy>
        <ixz>1.3e-05</ixz>
        <iyz>4e-06</iyz>
        </inertia>
    </inertial>
    <visual name="right_hip_roll_visual">
        <pose>0 0 0 0 0 0</pose>
        <geometry>
        <mesh> 
            <uri>package://digit_sdf_model/visual/hip-yaw-housing-mirror.obj</uri> 
        </mesh>
        </geometry>
    </visual>
    <collision name="right_hip_roll_collision_0000">
        <pose>0 0 0 0 0 0</pose>
        <geometry>
          <mesh>
            <uri>package://digit_sdf_model/collision/hip-yaw-housing_parts/hip-yaw-housing_convex_piece_000.obj</uri>
          </mesh>
        </geometry>
      </collision>
      <collision name="right_hip_roll_collision_0001">
        <pose>0 0 0 0 0 0</pose>
        <geometry>
          <mesh>
            <uri>package://digit_sdf_model/collision/hip-yaw-housing_parts/hip-yaw-housing_convex_piece_001.obj</uri>
          </mesh>
        </geometry>
    </collision>
</link>
<link name="right_hip_yaw">
    <pose>0 0 0 0 0 0 </pose>
    <inertial>
        <pose>1e-05 0.001945 0.042033 0 0 0</pose>
        <mass>0.818753</mass>
        <inertia>
        <ixx>0.001627</ixx>
        <iyy>0.001929</iyy>
        <izz>0.00077</izz>
        <ixy>1e-06</ixy>
        <ixz>2e-06</ixz>
        <iyz>-5.3e-05</iyz>
        </inertia>
    </inertial>
    <visual name="right_hip_yaw_visual">
        <pose relative_to="right_hip_yaw_joint">0 0 0 0 0 0</pose>
        <geometry>
        <mesh>
            <uri>package://digit_sdf_model/visual/hip-pitch-housing-mirror.obj</uri> 
        </mesh>
        </geometry>
    </visual>
</link>
<link name="right_hip_pitch">
    <pose relative_to="right_hip_pitch_joint">0 0 0 0 -1.57 0</pose>
    <inertial>
        <pose>0.060537 -0.000521 -0.038857 0 0 0</pose>
        <mass>6.244279</mass>
        <inertia>
        <ixx>0.011533</ixx>
        <iyy>0.033345</iyy>
        <izz>0.033958</izz>
        <ixy>0.000171</ixy>
        <ixz>0.000148</ixz>
        <iyz>-0.000178</iyz>
        </inertia>
    </inertial>
    <visual name="right_hip_pitch_visual">
        <pose relative_to="right_hip_pitch_joint">0 0 0 0 0 0</pose>
        <geometry>
        <mesh> 
            <uri>package://digit_sdf_model/visual/hip-pitch-mirror.obj</uri> 
        </mesh>
        </geometry>
    </visual>
    <collision name="right_hip_pitch_collision_0000">
        <pose relative_to="right_hip_pitch_joint">0 0 0 0 0 0</pose>
        <geometry>
          <mesh>
            <uri>package://digit_sdf_model/collision/hip-pitch-mirror_parts/hip-pitch-mirror_convex_piece_000.obj</uri>
          </mesh>
        </geometry>
    </collision>
    <collision name="right_hip_pitch_collision_0001">
        <pose relative_to="right_hip_pitch_joint">0 0 0 0 0 0</pose>
        <geometry>
          <mesh>
            <uri>package://digit_sdf_model/collision/hip-pitch-mirror_parts/hip-pitch-mirror_convex_piece_001.obj</uri>
          </mesh>
        </geometry>
    </collision>
    <collision name="right_hip_pitch_collision_0002">
        <pose relative_to="right_hip_pitch_joint">0 0 0 0 0 0</pose>
        <geometry>
          <mesh>
            <uri>package://digit_sdf_model/collision/hip-pitch-mirror_parts/hip-pitch-mirror_convex_piece_002.obj</uri>
          </mesh>
        </geometry>
    </collision>
    <collision name="right_hip_pitch_collision_0003">
        <pose relative_to="right_hip_pitch_joint">0 0 0 0 0 0</pose>
        <geometry>
          <mesh>
            <uri>package://digit_sdf_model/collision/hip-pitch-mirror_parts/hip-pitch-mirror_convex_piece_003.obj</uri>
          </mesh>
        </geometry>
    </collision>
</link>
<link name="right_knee">
    <pose relative_to="right_knee_joint">0 0 0 0 -1.57 0</pose>
    <inertial>
        <pose>0.045641 -0.042154 0.001657 0 0 0</pose>
        <mass>1.227077</mass>
        <inertia>
        <ixx>0.002643</ixx>
        <iyy>0.005098</iyy>
        <izz>0.007019</izz>
        <ixy>0.001832</ixy>
        <ixz>6.6e-05</ixz>
        <iyz>-4.5e-05</iyz>
        </inertia>
    </inertial>
    <visual name="right_knee_visual">
        <pose relative_to="right_knee_joint">0 0 0 0 0 0</pose>
        <geometry>
        <mesh> 
            <uri>package://digit_sdf_model/visual/knee-mirror.obj</uri> 
        </mesh>
        </geometry>
    </visual>
</link>
<link name="right_shin">
    <pose relative_to="right_knee_to_shin_joint">0 0 0 0 -1.57 0</pose>
    <inertial>
        <pose>0.174265 -0.010265 0.00107 0 0 0</pose>
        <mass>0.895793</mass>
        <inertia>
        <ixx>0.001128</ixx>
        <iyy>0.022492</iyy>
        <izz>0.022793</izz>
        <ixy>-0.001098</ixy>
        <ixz>0.000196</ixz>
        <iyz>3e-06</iyz>
        </inertia>
    </inertial>
    <visual name="right_shin_visual">
        <pose relative_to="right_knee_to_shin_joint">0 0 0 0 0 0</pose>
        <geometry>
        <mesh> 
            <uri>package://digit_sdf_model/visual/shin-mirror.obj</uri> 
        </mesh>
        </geometry>
    </visual>
    <collision name="right_shin_geom_1">
        <pose relative_to="right_knee_to_shin_joint">0.23 0 0 0 1.5708 0</pose>
        <geometry>
            <cylinder>
                <radius>0.03</radius>
                <length>0.343</length>
            </cylinder>
        </geometry>
    </collision>
    <collision name="right_shin_geom_2">
        <pose relative_to="right_knee_to_shin_joint">0.125 -0.009 0 -1.5708 1.466 0</pose>
        <geometry>
            <cylinder>
                <radius>0.05</radius>
                <length>0.2</length>
            </cylinder>
        </geometry>
    </collision>
</link>
<link name="right_tarsus">
    <pose relative_to="right_shin_to_tarsus_joint">0 0 0 0 -1.57 0</pose>
    <inertial>
        <pose>0.100777 0.029183 0.000678 0 0 0</pose>
        <mass>1.322865</mass>
        <inertia>
        <ixx>0.000932</ixx>
        <iyy>0.016409</iyy>
        <izz>0.016501</izz>
        <ixy>-0.00061</ixy>
        <ixz>0.000102</ixz>
        <iyz>-9e-06</iyz>
        </inertia>
    </inertial>
    <visual name="right_tarsus_visual">
        <pose relative_to="right_shin_to_tarsus_joint">0 0 0 0 0 0</pose>
        <geometry>
        <mesh> 
            <uri>package://digit_sdf_model/visual/tarsus-mirror.obj</uri> 
        </mesh>
        </geometry>
    </visual>
    <collision name="right_tarsus_collision_000">
        <pose relative_to="right_shin_to_tarsus_joint">0 0 0 3.14 0 0</pose>
        <geometry>
          <mesh>
            <uri>package://digit_sdf_model/collision/tarsus_parts/tarsus_convex_piece_000.obj</uri>
          </mesh>
        </geometry>
    </collision>
    <collision name="right_tarsus_collison_001">
        <pose relative_to="right_shin_to_tarsus_joint">0 0 0 3.14 0 0</pose>
        <geometry>
          <mesh>
            <uri>package://digit_sdf_model/collision/tarsus_parts/tarsus_convex_piece_001.obj</uri>
          </mesh>
        </geometry>
    </collision>
    <collision name="right_tarsus_collision_002">
        <pose relative_to="right_shin_to_tarsus_joint">0 0 0 3.14 0 0</pose>
        <geometry>
          <mesh>
            <uri>package://digit_sdf_model/collision/tarsus_parts/tarsus_convex_piece_002.obj</uri>
          </mesh>
        </geometry>
    </collision>
    <collision name="right_tarsus_collision_003">
        <pose relative_to="right_shin_to_tarsus_joint">0 0 0 3.14 0 0</pose>
        <geometry>
          <mesh>
            <uri>package://digit_sdf_model/collision/tarsus_parts/tarsus_convex_piece_003.obj</uri>
          </mesh>
        </geometry>
    </collision>
</link>
<link name="right_toe_pitch">
    <pose relative_to="right_toe_pitch_joint">0 0 0 0 -1.57 0</pose>
    <inertial>
        <pose>-0.000141 -2e-06 3e-06 0 0 0</pose>
        <mass>0.043881</mass>
        <inertia>
        <ixx>5e-06</ixx>
        <iyy>8e-06</iyy>
        <izz>4e-06</izz>
        <ixy>0</ixy>
        <ixz>0</ixz>
        <iyz>0</iyz>
        </inertia>
    </inertial>
    <visual name="right_toe_pitch_visual">
        <pose relative_to="right_toe_pitch_joint">0 0 0 0 0 0</pose>
        <geometry>
        <mesh> 
            <uri>package://digit_sdf_model/visual/toe-pitch-mirror.obj</uri> 
        </mesh>
        </geometry>
    </visual>
</link>
<link name="right_toe_roll">
    <pose relative_to="right_toe_roll_joint">0 0 0 0 -1.57 0</pose>
    <inertial>
        <pose>9e-06 0.028084 -0.023204 0 0 0</pose>
        <mass>0.531283</mass>
        <inertia>
        <ixx>0.00187</ixx>
        <iyy>0.001616</iyy>
        <izz>0.000843</izz>
        <ixy>0</ixy>
        <ixz>0</ixz>
        <iyz>-0.000566</iyz>
        </inertia>
    </inertial>
    <visual name="right_toe_roll_visual">
        <pose relative_to="right_toe_roll_joint">0 0 0 0 0 0</pose>
        <geometry>
        <mesh> 
            <uri>package://digit_sdf_model/visual/toe-roll-mirror.obj</uri> 
        </mesh>
        </geometry>
    </visual>
    <collision name="right_toe_geom_1">
        <pose relative_to="right_toe_roll_joint">0 0.0437 -0.0255 1.0472 0 0</pose>
        <geometry>
            <box>
                <size>0.04 0.1175 0.0115</size>
            </box>
        </geometry>
    </collision>
</link>
<joint name="right_hip_yaw_joint" type="continuous">
    <pose>-0.0505 0 0.044 0 -1.57 0</pose>
    <axis>
        <xyz>0 0 1</xyz> 
        <limit> 
            <lower>-0.698132</lower>
            <upper>0.698132</upper>
            <effort>1.4</effort>
            <velocity>10</velocity>
        </limit>
    </axis>
    <parent>right_hip_roll</parent>
    <child>right_hip_yaw</child>
</joint>
<joint name="right_hip_pitch_joint" type="continuous">
    <pose relative_to="right_hip_yaw_joint">0 -0.004 0.068 1.57079632679 -0.785398163397 -3.14159265359</pose>
    <axis>
        <xyz>0 0 -1</xyz>
        <limit> 
            <lower>-1.0472</lower>
            <upper>1.5708</upper>
            <effort>12.5</effort>
            <velocity>10</velocity>
        </limit>
    </axis>
    <parent>right_hip_yaw</parent>
    <child>right_hip_pitch</child>
</joint>
<joint name="right_knee_joint" type="continuous">
    <pose relative_to="right_hip_pitch_joint">0.12 0 0.0045 0 0 1.57079632679</pose>
    <axis>
        <xyz>0 0 1</xyz>
        <limit> 
            <lower>-1.39626</lower>
            <upper>1.019272</upper>
            <effort>1.4</effort>
            <velocity>10</velocity>
        </limit>
    </axis>
    <parent>right_hip_pitch</parent>
    <child>right_knee</child>
</joint>
<joint name="right_knee_to_shin_joint" type="fixed">
    <pose relative_to="right_knee_joint">0.060677 -0.047406 0 0 0 0</pose>
    <axis>
        <xyz>0 0 1</xyz>
        <limit> 
            <lower>-0.35</lower>
            <upper>0.35</upper>
            <effort>0</effort>
            <velocity>10</velocity>
        </limit>
        <dynamics>
            <damping>0.1</damping>
        </dynamics>
    </axis>
    <parent>right_knee</parent>
    <child>right_shin</child>
</joint>
<joint name="right_shin_to_tarsus_joint" type="continuous">
    <pose relative_to="right_knee_to_shin_joint">0.434759 -0.02 0 0 0 -1.79769</pose>
    <axis>
        <xyz>0 0 1</xyz>
        <limit> 
            <lower>-1.2497</lower>
            <upper>0.8779</upper>
            <effort>0</effort>
            <velocity>20</velocity>
        </limit>
    </axis>
    <parent>right_shin</parent>
    <child>right_tarsus</child>
</joint>
<joint name="right_toe_pitch_joint" type="continuous">
    <pose relative_to="right_shin_to_tarsus_joint">0.408 0.04 0 0 0 -1.1956</pose>
    <axis>
        <xyz>0 0 1</xyz>
        <limit> 
            <lower>-0.785398163397</lower>
            <upper>0.785398163397</upper>
            <effort>0.9</effort>
            <velocity>11.5</velocity>
        </limit>
    </axis>
    <parent>right_tarsus</parent>
    <child>right_toe_pitch</child>
</joint>
<joint name="right_toe_roll_joint" type="continuous">
    <pose relative_to="right_toe_pitch_joint">0 0 0 0 1.5708 0</pose>
    <axis>
        <xyz>0 0 1</xyz>
        <limit> 
            <lower>-0.6109</lower>
            <upper>0.6109</upper>
            <effort>0.9</effort>
            <velocity>11.5</velocity>
        </limit>
    </axis>
    <parent>right_toe_pitch</parent>
    <child>right_toe_roll</child>
</joint>
</model>
</sdf>