<?xml version='1.0'?>
<sdf xmlns:drake="http://drake.mit.edu" version="1.9">
<model name="digit_left_leg">
<link name="left_hip_roll">
    <pose>0 0 0 0 0 0 </pose>
    <inertial>
        <pose>-0.001967 0.000244 0.031435 0 0 0</pose>
        <mass>0.915088</mass>
        <inertia>
        <ixx>0.001017</ixx>
        <iyy>0.001148</iyy>
        <izz>0.000766</izz>
        <ixy>-3e-06</ixy>
        <ixz>1.3e-05</ixz>
        <iyz>-4e-06</iyz>
        </inertia>
    </inertial>
    <visual name="left_hip_roll_visual">
        <pose>0 0 0 0 0 0</pose>
        <geometry>
        <mesh> 
            <uri>package://drail_drake/model_files/digit/visual/hip-yaw-housing.obj</uri> 
        </mesh>
        </geometry>
    </visual>
    <collision name="left_hip_roll_collision_0000">
        <pose>0 0 0 0 0 0</pose>
        <geometry>
          <mesh>
            <uri>package://digit_sdf_model/collision/hip-yaw-housing_parts/hip-yaw-housing_convex_piece_000.obj</uri>
            <drake:declare_convex/>
          </mesh>
        </geometry>
      </collision>
      <collision name="left_hip_roll_collision_0001">
        <pose>0 0 0 0 0 0</pose>
        <geometry>
          <mesh>
            <uri>package://digit_sdf_model/collision/hip-yaw-housing_parts/hip-yaw-housing_convex_piece_001.obj</uri>
            <drake:declare_convex/>
          </mesh>
        </geometry>
    </collision>
</link>
<link name="left_hip_yaw">
    <pose>0 0 0 0 0 0 </pose>
    <inertial>
        <pose>1e-05 -0.001945 0.042033 0 0 0</pose>
        <mass>0.818753</mass>
        <inertia>
        <ixx>0.001627</ixx>
        <iyy>0.001929</iyy>
        <izz>0.00077</izz>
        <ixy>-1e-06</ixy>
        <ixz>2e-06</ixz>
        <iyz>5.3e-05</iyz>
        </inertia>
    </inertial>
    <visual name="left_hip_yaw_visual">
        <pose relative_to="left_hip_yaw_joint">0 0 0 0 0 0</pose>
        <geometry>
        <mesh>
            <uri>package://drail_drake/model_files/digit/visual/hip-pitch-housing.obj</uri> 
        </mesh>
        </geometry>
    </visual>
</link>
<link name="left_hip_pitch">
    <pose relative_to="left_hip_pitch_joint">0 0 0 0 -1.5708 0</pose>
    <inertial>
        <pose>0.060537 0.000521 -0.038857 0 0 0</pose>
        <mass>6.244279</mass>
        <inertia>
        <ixx>0.011533</ixx>
        <iyy>0.033345</iyy>
        <izz>0.033958</izz>
        <ixy>-0.000171</ixy>
        <ixz>0.000148</ixz>
        <iyz>0.000178</iyz>
        </inertia>
    </inertial>
    <visual name="left_hip_pitch_visual">
        <pose relative_to="left_hip_pitch_joint">0 0 0 0 0 0</pose>
        <geometry>
        <mesh> 
            <uri>package://drail_drake/model_files/digit/visual/hip-pitch.obj</uri> 
        </mesh>
        </geometry>
    </visual>
    <collision name="left_hip_pitch_collision_000">
        <pose relative_to="left_hip_pitch_joint">0 0 0 0 0 0</pose>
        <geometry>
          <mesh>
            <uri>package://digit_sdf_model/collision/hip-pitch_parts/hip-pitch_convex_piece_000.obj</uri>
            <drake:declare_convex/>
          </mesh>
        </geometry>
    </collision>
    <collision name="left_hip_pitch_collision_001">
        <pose relative_to="left_hip_pitch_joint">0 0 0 0 0 0</pose>
        <geometry>
          <mesh>
            <uri>package://digit_sdf_model/collision/hip-pitch_parts/hip-pitch_convex_piece_001.obj</uri>
            <drake:declare_convex/>
          </mesh>
        </geometry>
    </collision>
    <collision name="left_hip_pitch_collision_002">
        <pose relative_to="left_hip_pitch_joint">0 0 0 0 0 0</pose>
        <geometry>
          <mesh>
            <uri>package://digit_sdf_model/collision/hip-pitch_parts/hip-pitch_convex_piece_002.obj</uri>
            <drake:declare_convex/>
          </mesh>
        </geometry>
    </collision>
    <collision name="left_hip_pitch_collision_003">
        <pose relative_to="left_hip_pitch_joint">0 0 0 0 0 0</pose>
        <geometry>
          <mesh>
            <uri>package://digit_sdf_model/collision/hip-pitch_parts/hip-pitch_convex_piece_003.obj</uri>
            <drake:declare_convex/>
          </mesh>
        </geometry>
    </collision>
</link>
<link name="left_achilles_rod">
    <pose relative_to="left_hip_pitch_frame">0 0 0 1.5708 0 0</pose>
    <inertial>
        <pose>0.2506 0 0 0 0 0</pose>
        <mass>0.178148</mass>
        <inertia>
            <ixx>3e-06</ixx>
            <iyy>0.004501</iyy>
            <izz>0.004501</izz>
            <ixy>0</ixy>
            <ixz>0</ixz>
            <iyz>0</iyz>
        </inertia>
    </inertial>
    <visual name="left_achilles_rod_visual">
        <pose relative_to="left_achilles_rod">0 0 0 0 0 0</pose>
        <geometry>
            <mesh>
                <uri>package://drail_drake/model_files/digit/visual/achilles-rod.obj</uri>
            </mesh>
        </geometry>
    </visual>
    <!-- <visual name="heel_spring_indicator">
        <pose relative_to="left_achilles_rod">0.5 0 0 0 0 0</pose>
        <geometry>
          <box>
            <size>0.01 0.01 0.01</size>
          </box>
        </geometry>
      </visual> -->
    <collision name="left_achilles_rod_collision">
        <pose relative_to="left_achilles_rod">0.25 0 0 0.0698132 1.5708 0</pose>
        <geometry>
            <capsule>
                <radius>0.007</radius>
                <length>0.5</length>
            </capsule>
        </geometry>
    </collision>
</link>
<link name="left_knee">
    <pose relative_to="left_knee_joint">0 0 0 0 -1.5708 0</pose>
    <inertial>
        <pose>0.045641 0.042154 0.001657 0 0 0</pose>
        <mass>1.227077</mass>
        <inertia>
        <ixx>0.002643</ixx>
        <iyy>0.005098</iyy>
        <izz>0.007019</izz>
        <ixy>-0.001832</ixy>
        <ixz>6.6e-05</ixz>
        <iyz>4.5e-05</iyz>
        </inertia>
    </inertial>
    <visual name="left_knee_visual">
        <pose relative_to="left_knee_joint">0 0 0 0 0 0</pose>
        <geometry>
        <mesh> 
            <uri>package://drail_drake/model_files/digit/visual/knee.obj</uri> 
        </mesh>
        </geometry>
    </visual>
</link>
<link name="left_shin">
    <pose relative_to="left_knee_to_shin_joint">0 0 0 0 -1.5708 0</pose>
    <inertial>
        <pose>0.174265 0.010265 0.00107 0 0 0</pose>
        <mass>0.895793</mass>
        <inertia>
        <ixx>0.001128</ixx>
        <iyy>0.022492</iyy>
        <izz>0.022793</izz>
        <ixy> 0.001098</ixy>
        <ixz>0.000196</ixz>
        <iyz>-3e-06</iyz>
        </inertia>
    </inertial>
    <visual name="left_shin_visual">
        <pose relative_to="left_knee_to_shin_joint">0 0 0 0 0 0</pose>
        <geometry>
        <mesh> 
            <uri>package://drail_drake/model_files/digit/visual/shin-no-shell.obj</uri> 
        </mesh>
        </geometry>
    </visual>
    <collision name="left_shin_geom_1">
        <pose relative_to="left_knee_to_shin_joint">0.23 0 0 0 1.5708 0</pose>
        <geometry>
            <cylinder>
                <radius>0.03</radius>
                <length>0.343</length>
            </cylinder>
        </geometry>
    </collision>
    <collision name="left_shin_geom_2">
        <pose relative_to="left_knee_to_shin_joint">0.125 0.009 0 1.5708 1.466 0</pose>
        <geometry>
            <cylinder>
                <radius>0.05</radius>
                <length>0.2</length>
            </cylinder>
        </geometry>
    </collision>
</link>
<link name="left_tarsus">
    <pose relative_to="left_shin_to_tarsus_joint">0 0 0 0 -1.5708 0</pose>
    <inertial>
        <pose>0.100777 -0.029183 0.000678 0 0 0</pose>
        <mass>1.322865</mass>
        <inertia>
        <ixx>0.000932</ixx>
        <iyy>0.016409</iyy>
        <izz>0.016501</izz>
        <ixy>0.00061</ixy>
        <ixz>0.000102</ixz>
        <iyz>9e-06</iyz>
        </inertia>
    </inertial>
    <visual name="left_tarsus_visual">
        <pose relative_to="left_shin_to_tarsus_joint">0 0 0 0 0 0</pose>
        <geometry>
        <mesh> 
            <uri>package://drail_drake/model_files/digit/visual/tarsus.obj</uri> 
        </mesh>
        </geometry>
    </visual>
    <collision name="left_tarsus_collision_0000">
        <pose relative_to="left_shin_to_tarsus_joint">0 0 0 0 0 0</pose>
        <geometry>
          <mesh>
            <uri>package://digit_sdf_model/collision/tarsus_parts/tarsus_convex_piece_000.obj</uri>
            <drake:declare_convex/>
          </mesh>
        </geometry>
    </collision>
    <collision name="left_tarsus_collision_001">
        <pose relative_to="left_shin_to_tarsus_joint">0 0 0 0 0 0</pose>
        <geometry>
          <mesh>
            <uri>package://digit_sdf_model/collision/tarsus_parts/tarsus_convex_piece_001.obj</uri>
            <drake:declare_convex/>
          </mesh>
        </geometry>
    </collision>
    <collision name="left_tarsus_geom_collision_002">
        <pose relative_to="left_shin_to_tarsus_joint">0 0 0 0 0 0</pose>
        <geometry>
          <mesh>
            <uri>package://digit_sdf_model/collision/tarsus_parts/tarsus_convex_piece_002.obj</uri>
            <drake:declare_convex/>
          </mesh>
        </geometry>
    </collision>
    <collision name="left_tarsus_collison_003">
        <pose relative_to="left_shin_to_tarsus_joint">0 0 0 0 0 0</pose>
        <geometry>
          <mesh>
            <uri>package://digit_sdf_model/collision/tarsus_parts/tarsus_convex_piece_003.obj</uri>
            <drake:declare_convex/>
          </mesh>
        </geometry>
    </collision>
</link>
<link name="left_heel_spring">
    <pose relative_to="left_heel_spring_joint">0 0 0 0 0 0</pose>
    <inertial>
        <pose>0.049086 0.004739 -4.5e-05 0 0 0</pose>
        <mass>0.230018</mass>
        <inertia>
        <ixx>5.5e-05</ixx>
        <iyy>0.00074</iyy>
        <izz>0.000701</izz>
        <ixy>1.5e-05</ixy>
        <ixz>1e-06</ixz>
        <iyz>0</iyz>
        </inertia>
    </inertial>
    <visual name="left_heel_spring_visual">
        <pose relative_to="left_heel_spring_joint">0 0 0 0 0 0</pose>
        <geometry>
        <mesh> 
            <uri>package://drail_drake/model_files/digit/visual/heel-spring.obj</uri> 
        </mesh>
        </geometry>
    </visual>
    <!-- <visual name="heel_spring_indicator">
        <pose relative_to="left_heel_spring_frame">0 0 0 0 0 0</pose>
        <geometry>
          <box>
            <size>0.01 0.01 0.01</size>
          </box>
        </geometry>
    </visual> -->
</link>
<link name ="left_toe_A">
    <pose relative_to="left_toe_A_joint">0 0 0 0 1.5708 0</pose>
    <inertial>
        <pose>0.005161 1e-06 -0.002248 0 0 0</pose>
        <mass>0.139557</mass>
        <inertia>
        <ixx>2.9e-05</ixx>
        <iyy>5.8e-05</iyy>
        <izz>7.4e-05</izz>
        <ixy>0</ixy>
        <ixz>-4e-06</ixz>
        <iyz>0</iyz>
        </inertia>
    </inertial>
    <visual name="left_toe_A_visual">
        <pose relative_to="left_toe_A">0 0 0 3.14159 1.5526449 -1.5708</pose>
        <geometry>
        <mesh> 
            <uri>package://drail_drake/model_files/digit/visual/toe-output.obj</uri> 
        </mesh>
        </geometry>
    </visual>
</link>
<link name ="left_toe_A_rod">
    <pose relative_to="left_toe_A_rod_joint">0 0 0 0 3.14159 0</pose>
    <inertial>
        <pose>0.005161 1e-06 -0.002248 0 0 0</pose>
        <mass>0.139557</mass>
        <inertia>
        <ixx>2.9e-05</ixx>
        <iyy>5.8e-05</iyy>
        <izz>7.4e-05</izz>
        <ixy>0</ixy>
        <ixz>-4e-06</ixz>
        <iyz>0</iyz>
        </inertia>
    </inertial>
    <visual name="left_toe_A_rod_visual">
        <pose relative_to="left_toe_A_rod">0 0 0 0 0 0</pose>
        <geometry>
        <mesh> 
            <uri>package://drail_drake/model_files/digit/visual/toe-A-rod.obj</uri> 
        </mesh>
        </geometry>
    </visual>
    <!-- <visual name="left_toe_A_rod_indicator">
        <pose relative_to="left_toe_A_rod">0 0 0 0 0 0</pose>
        <geometry>
          <box>
            <size>0.01 0.01 0.01</size>
          </box>
        </geometry>
    </visual>
    <visual name="left_toe_A_rod_tail_indicator">
        <pose relative_to="left_toe_A_rod">0.34 0 0 0 0 0</pose>
        <geometry>
          <box>
            <size>0.01 0.01 0.01</size>
          </box>
        </geometry>
    </visual> -->
    <!-- <collision name="left_toe_A_rod_geom_1">
        <pose relative_to="left_toe_A_rod">0.17 0 0 0.0698132 1.5708 0</pose>
        <geometry>
            <capsule>
                <radius>0.007</radius>
                <length>0.28</length>
            </capsule>
        </geometry>
    </collision> -->
    <collision name="left_toe_A_collison_000">
        <pose relative_to="left_toe_A_rod">0 0 0 0 0 0</pose>
        <geometry>
          <mesh>
            <uri>package://digit_sdf_model/collision/toe-A-rod_parts/toe-A-rod_convex_piece_000.obj</uri>
            <drake:declare_convex/>
          </mesh>
        </geometry>
      </collision>
      <collision name="left_toe_A_collison_001">
        <pose relative_to="left_toe_A_rod">0 0 0 0 0 0</pose>
        <geometry>
          <mesh>
            <uri>package://digit_sdf_model/collision/toe-A-rod_parts/toe-A-rod_convex_piece_001.obj</uri>
            <drake:declare_convex/>
          </mesh>
        </geometry>
      </collision>
      <collision name="left_toe_A_collision_002">
        <pose relative_to="left_toe_A_rod">0 0 0 0 0 0</pose>
        <geometry>
          <mesh>
            <uri>package://digit_sdf_model/collision/toe-A-rod_parts/toe-A-rod_convex_piece_002.obj</uri>
            <drake:declare_convex/>
          </mesh>
        </geometry>
    </collision>
</link>
<link name ="left_toe_B">
    <pose relative_to="left_toe_B_joint">0 0 0 0 1.5708 0</pose>
    <inertial>
        <pose>0.005161 1e-06 -0.002248 0 0 0</pose>
        <mass>0.139557</mass>
        <inertia>
        <ixx>2.9e-05</ixx>
        <iyy>5.8e-05</iyy>
        <izz>7.4e-05</izz>
        <ixy>0</ixy>
        <ixz>-4e-06</ixz>
        <iyz>0</iyz>
        </inertia>
    </inertial>
    <visual name="left_toe_B_visual">
        <pose relative_to="left_toe_B_joint">0 0 0 1.5708 0 0</pose>
        <geometry>
        <mesh> 
            <uri>package://drail_drake/model_files/digit/visual/toe-output.obj</uri> 
        </mesh>
        </geometry>
    </visual>
</link>
<link name ="left_toe_B_rod">
    <pose relative_to="left_toe_B_rod_joint">0 0 0 0 0 0</pose>
    <inertial>
        <pose>0.142991 0 0 0 0 0</pose>
        <mass>0.079507</mass>
        <inertia>
        <ixx>1e-06</ixx>
        <iyy>0.000768</iyy>
        <izz>0.000768</izz>
        <ixy>0</ixy>
        <ixz>0</ixz>
        <iyz>0</iyz>
        </inertia>
    </inertial>
    <visual name="left_toe_B_rod_visual">
        <pose relative_to="left_toe_B_rod_joint">0 0 0 0 0 0</pose>
        <geometry>
        <mesh> 
            <uri>package://drail_drake/model_files/digit/visual/toe-B-rod.obj</uri> 
        </mesh>
        </geometry>
    </visual>
    <!-- <visual name="left_toe_B_rod_indicator">
        <pose relative_to="left_toe_B_rod_joint">0 0 0 0 0 0</pose>
        <geometry>
          <box>
            <size>0.01 0.01 0.01</size>
          </box>
        </geometry>
    </visual>
    <visual name="left_toe_B_rod_tail_indicator">
        <pose relative_to="left_toe_B_rod">0.288 0 0 0 0 0</pose>
        <geometry>
          <box>
            <size>0.01 0.01 0.01</size>
          </box>
        </geometry>
    </visual> -->
    <collision name="left_toe_B_rod_geom_1">
        <pose relative_to="left_toe_B_rod_joint">0.17 0 0 0.0698132 1.5708 0</pose>
        <geometry>
            <capsule>
                <radius>0.007</radius>
                <length>0.22</length>
            </capsule>
        </geometry>
    </collision>
</link>
<link name="left_toe_pitch">
    <pose relative_to="left_toe_pitch_joint">0 0 0 0 -1.5708 0</pose>
    <inertial>
        <pose>-0.000141 2e-06 3e-06 0 0 0</pose>
        <mass>0.043881</mass>
        <inertia>
        <ixx>5e-06</ixx>
        <iyy>8e-06</iyy>
        <izz>4e-06</izz>
        <ixy>0</ixy>
        <ixz>0</ixz>
        <iyz>0</iyz>
        </inertia>
    </inertial>
    <visual name="left_toe_pitch_visual">
        <pose relative_to="left_toe_pitch_joint">0 0 0 0 0 0</pose>
        <geometry>
        <mesh> 
            <uri>package://drail_drake/model_files/digit/visual/toe-pitch.obj</uri> 
        </mesh>
        </geometry>
    </visual>
</link>
<link name="left_toe_roll">
    <pose relative_to="left_toe_roll_joint">0 0 0 0 -1.5708 0</pose>
    <inertial>
        <pose>9e-06 -0.028084 -0.023204 0 0 0</pose>
        <mass>0.531283</mass>
        <inertia>
        <ixx>0.00187</ixx>
        <iyy>0.001616</iyy>
        <izz>0.000843</izz>
        <ixy>0</ixy>
        <ixz>0</ixz>
        <iyz>0.000566</iyz>
        </inertia>
    </inertial>
    <visual name="left_toe_roll_visual">
        <pose relative_to="left_toe_roll_joint">0 0 0 0 0 0</pose>
        <geometry>
        <mesh> 
            <uri>package://drail_drake/model_files/digit/visual/toe-roll.obj</uri> 
        </mesh>
        </geometry>
    </visual>
    <!-- <visual name="left_toe_roll_indicator_a">
        <pose relative_to="left_toe_roll_joint">0.0179 -0.009551 -0.054164 0 0 0</pose>
        <geometry>
          <box>
            <size>0.01 0.01 0.01</size>
          </box>
        </geometry>
      </visual>
      <visual name="left_toe_roll_indicator_b">
        <pose relative_to="left_toe_roll_joint">-0.0181 -0.009551 -0.054164 0 0 0</pose>
        <geometry>
          <box>
            <size>0.01 0.01 0.01</size>
          </box>
        </geometry>
      </visual> -->
      <collision name="left_toe_geom_1">
        <pose relative_to="left_toe_roll_joint">0 -0.0437 -0.0255 -1.0472 0 0</pose>
        <geometry>
            <box>
                <size>0.04 0.1175 0.0115</size>
            </box>
        </geometry>
    </collision>
</link>
<joint name="left_hip_yaw_joint" type="continuous">
    <pose>-0.0505 0 0.044 0 -1.5708 0</pose>
    <axis>
        <xyz>0 0 1</xyz> 
        <limit> 
            <lower>-0.698132</lower>
            <upper>0.698132</upper>
            <effort>1.4</effort>
            <velocity>10</velocity>
        </limit>
        <dynamics>
            <damping>1</damping>
            <friction>1</friction>
        </dynamics>
    </axis>
    <parent>left_hip_roll</parent>
    <child>left_hip_yaw</child>
    <drake:gear_ratio>50</drake:gear_ratio>
    <drake:rotor_inertia>0.0679</drake:rotor_inertia>
</joint>
<joint name="left_hip_pitch_joint" type="continuous">
    <pose relative_to="left_hip_yaw_joint">0 0.004 0.068 -1.57079632679 -0.785398163397 3.14159265359</pose>
    <axis>
        <xyz>0 0 -1</xyz>
        <limit> 
            <lower>-1.0472</lower>
            <upper>1.5708</upper>
            <effort>12.5</effort>
            <velocity>10</velocity>
        </limit>
        <dynamics>
            <damping>1</damping>
            <friction>0.5</friction>
        </dynamics>
    </axis>
    <parent>left_hip_yaw</parent>
    <child>left_hip_pitch</child>
    <drake:gear_ratio>16</drake:gear_ratio>
    <drake:rotor_inertia>0.120473</drake:rotor_inertia>
</joint>
<joint name="left_hip_pitch_to_achilles_joint" type="ball">
    <pose relative_to="left_hip_pitch_joint">0 0 0.046 0.07138397 0.0008726646 -1.4358824</pose>
    <axis>
        <xyz>0 0 1</xyz>
        <limit> 
            <velocity>10</velocity>
        </limit>
        <dynamics>
            <damping>0.01</damping>
        </dynamics>
    </axis>
    <parent>left_hip_pitch</parent>
    <child>left_achilles_rod</child>
</joint>
<frame name="left_hip_pitch_frame" attached_to="left_hip_pitch">
    <pose relative_to="left_hip_pitch_joint">0 0 0.046 0.07138397 0.0008726646 -1.4358824</pose>
</frame>
<frame name="left_achilles_rod_head_frame" attached_to="left_achilles_rod">
    <pose relative_to="left_achilles_rod">0 0 0 0 0 0</pose>
</frame>
<frame name="left_achilles_rod_tail_frame" attached_to="left_achilles_rod">
    <pose>0.5 0 0 0 0 0</pose>
</frame>
<joint name="left_knee_joint" type="revolute">
    <pose relative_to="left_hip_pitch_joint">0.12 0 0.0045 0 0 -1.57079632679</pose>
    <axis>
        <xyz>0 0 1</xyz>
        <limit> 
            <lower>-1.39626</lower>
            <upper>1.019272</upper>
            <effort>1.4</effort>
            <velocity>10</velocity>
        </limit>
        <dynamics>
            <damping>1</damping>
            <friction>0.5</friction>
        </dynamics>
    </axis>
    <parent>left_hip_pitch</parent>
    <child>left_knee</child>
    <drake:gear_ratio>16</drake:gear_ratio>
    <drake:rotor_inertia>0.120473</drake:rotor_inertia>
</joint>
<frame name="left_knee_spring_frame" attached_to="left_knee">
    <pose relative_to="left_knee_joint">0.14 0.09 0 0 0 0</pose>
</frame>
<joint name="left_knee_to_shin_joint" type="revolute">
    <pose relative_to="left_knee_joint">0.060677 0.047406 0 0 0 0</pose>
    <axis>
        <xyz>0 0 1</xyz>
        <limit> 
            <lower>-0.35</lower>
            <upper>0.35</upper>
            <effort>0</effort>
            <velocity>10</velocity>
        </limit>
        <dynamics>
            <spring_reference>0</spring_reference>
            <spring_stiffness>6000</spring_stiffness>
        </dynamics>
    </axis>
    <parent>left_knee</parent>
    <child>left_shin</child>
</joint>
<frame name="left_shin_frame" attached_to="left_shin">
    <pose relative_to="left_knee_to_shin_joint">0.079 0.042 0 0 0 0</pose>
</frame>
<joint name="left_shin_to_tarsus_joint" type="revolute">
    <pose relative_to="left_knee_to_shin_joint">0.434759 0.02 0 0 0 1.79769</pose>
    <axis>
        <xyz>0 0 1</xyz>
        <limit> 
            <lower>-1.2497</lower>
            <upper>0.8779</upper>
            <effort>0</effort>
            <velocity>20</velocity>
        </limit>
    </axis>
    <parent>left_shin</parent>
    <child>left_tarsus</child>
</joint>
<joint name="left_heel_spring_joint" type="revolute">
    <!-- <pose relative_to="left_shin_to_tarsus_joint">-0.01766 -0.029456 0.00104 0.07801622 0.005585054 2.719223</pose> -->
    <pose relative_to="left_shin_to_tarsus_joint">-0.01766 -0.029456 0.00104 -0.07801622 0 2.719223</pose>
    <axis>
        <xyz>0 0 1</xyz>
        <limit> 
            <lower>-0.10472</lower>
            <upper>0.10472</upper>
        </limit>
        <dynamics>
            <spring_reference>0</spring_reference>
            <spring_stiffness>4375</spring_stiffness>
        </dynamics>
    </axis>
    <parent>left_tarsus</parent>
    <child>left_heel_spring</child>
</joint>
<frame name="left_heel_spring_frame" attached_to="left_heel_spring">
    <pose relative_to="left_heel_spring">0.113789 -0.011056 0 0 0 0</pose>
</frame>
<joint name="left_toe_A_joint" type="revolute">
    <pose relative_to="left_shin_to_tarsus_joint">0.059 -0.034 -0.0276 -3.14159 0 1.5526449</pose>
    <axis>
        <xyz>0 0 1</xyz>
        <limit> 
            <lower>-0.807659838</lower>
            <upper>0.7850752775</upper>
        </limit>
        <dynamics>
            <damping>1</damping>
            <friction>1</friction>
        </dynamics>
    </axis>
    <parent>left_tarsus</parent>
    <child>left_toe_A</child>
    <drake:gear_ratio>50</drake:gear_ratio>
    <drake:rotor_inertia>0.036089</drake:rotor_inertia>
</joint>

<joint name="left_toe_A_rod_joint" type="ball">
    <pose relative_to="left_toe_A">0.009 -0.001 -0.057 0.005734119 0.03735005 -1.5437437</pose>
    <axis>
        <xyz>0 0 1</xyz>
        <dynamics>
            <damping>0.01</damping>
        </dynamics>
    </axis>
    <parent>left_toe_A</parent>
    <child>left_toe_A_rod</child>
</joint>
<frame name="left_toe_A_rod_tail_frame" attached_to="left_toe_A_rod">
    <pose>0.34 0 0 0 0 0</pose>
</frame>
<joint name="left_toe_B_joint" type="revolute">
    <pose relative_to="left_shin_to_tarsus_joint">0.111 -0.034 0.0276 0 0 -1.5526449</pose>
    <axis>
        <xyz>0 0 1</xyz>
        <limit> 
            <lower>-0.802851</lower>
            <upper>0.802851</upper>
        </limit>
        <dynamics>
            <damping>1</damping>
            <friction>1</friction>
        </dynamics>
    </axis>
    <parent>left_tarsus</parent>
    <child>left_toe_B</child>
    <drake:gear_ratio>50</drake:gear_ratio>
    <drake:rotor_inertia>0.036089</drake:rotor_inertia>
</joint>
<frame name="left_toe_B_rod_tail_frame" attached_to="left_toe_B_rod">
    <pose>0.288 0 0 0 0 0</pose>
</frame>
<joint name="left_toe_B_rod_joint" type="ball">
    <pose relative_to="left_toe_B">0.01 0 0.057 -0.003839724 -0.05375614 1.5418239</pose>
    <axis>
        <xyz>0 0 1</xyz>
        <dynamics>
            <damping>0.01</damping>
        </dynamics>
    </axis>
    <parent>left_toe_B</parent>
    <child>left_toe_B_rod</child>
</joint>

<joint name="left_toe_pitch_joint" type="revolute">
    <pose relative_to="left_shin_to_tarsus_joint">0.408 -0.04 0 0 0 1.1956</pose>
    <axis>
        <xyz>0 0 1</xyz>
        <limit> 
            <lower>-0.785398163397</lower>
            <upper>0.785398163397</upper>
            <effort>0.9</effort>
            <velocity>11.5</velocity>
        </limit>
    </axis>
    <parent>left_tarsus</parent>
    <child>left_toe_pitch</child>
    <drake:gear_ratio>16</drake:gear_ratio>
    <drake:rotor_inertia>0.120473</drake:rotor_inertia>
</joint>
<joint name="left_toe_roll_joint" type="continuous">
    <pose relative_to="left_toe_pitch_joint">0 0 0 0 1.5708 0</pose>
    <axis>
        <xyz>0 0 1</xyz>
        <limit> 
            <lower>-0.6109</lower>
            <upper>0.6109</upper>
            <effort>0.9</effort>
            <velocity>11.5</velocity>
        </limit>
    </axis>
    <parent>left_toe_pitch</parent>
    <child>left_toe_roll</child>
    <drake:gear_ratio>16</drake:gear_ratio>
    <drake:rotor_inertia>0.120473</drake:rotor_inertia>
</joint>
<frame name="left_toe_roll_A_rod_frame" attached_to="left_toe_roll">
    <pose relative_to="left_toe_roll_joint">0.0179 -0.009551 -0.054164 0 0 0</pose>
</frame>
<frame name="left_toe_roll_B_rod_frame" attached_to="left_toe_roll">
    <pose relative_to="left_toe_roll_joint">-0.0181 -0.009551 -0.054164 0 0 0</pose>
</frame>
<drake:linear_bushing_rpy>
    <drake:bushing_frameA>left_heel_spring_frame</drake:bushing_frameA>
    <drake:bushing_frameC>left_achilles_rod_tail_frame</drake:bushing_frameC>
    <drake:bushing_torque_stiffness>0 0 0</drake:bushing_torque_stiffness>
    <drake:bushing_force_stiffness>10000 10000 10000</drake:bushing_force_stiffness>
    <drake:bushing_torque_damping>0 0 0</drake:bushing_torque_damping>
    <drake:bushing_force_damping>50 50 50</drake:bushing_force_damping>
</drake:linear_bushing_rpy>
<drake:linear_bushing_rpy>
    <drake:bushing_frameA>left_toe_A_rod_tail_frame</drake:bushing_frameA>
    <drake:bushing_frameC>left_toe_roll_A_rod_frame</drake:bushing_frameC>
    <drake:bushing_torque_stiffness>0 0 0</drake:bushing_torque_stiffness>
    <drake:bushing_force_stiffness>1000 1000 1000</drake:bushing_force_stiffness>
    <drake:bushing_torque_damping>0 0 0</drake:bushing_torque_damping>
    <drake:bushing_force_damping>5 5 5</drake:bushing_force_damping>
</drake:linear_bushing_rpy>
<drake:linear_bushing_rpy>
    <drake:bushing_frameA>left_toe_B_rod_tail_frame</drake:bushing_frameA>
    <drake:bushing_frameC>left_toe_roll_B_rod_frame</drake:bushing_frameC>
    <drake:bushing_torque_stiffness>0 0 0</drake:bushing_torque_stiffness>
    <drake:bushing_force_stiffness>1000 1000 1000</drake:bushing_force_stiffness>
    <drake:bushing_torque_damping>0 0 0</drake:bushing_torque_damping>
    <drake:bushing_force_damping>1 1 1</drake:bushing_force_damping>
</drake:linear_bushing_rpy>
<drake:linear_bushing_rpy>
    <drake:bushing_frameA>left_knee_spring_frame</drake:bushing_frameA>
    <drake:bushing_frameC>left_shin_frame</drake:bushing_frameC>
    <drake:bushing_torque_stiffness>0 0 0</drake:bushing_torque_stiffness>
    <drake:bushing_force_stiffness>4000 4000 4000</drake:bushing_force_stiffness>
    <drake:bushing_torque_damping>0 0 0</drake:bushing_torque_damping>
    <drake:bushing_force_damping>10 10 10</drake:bushing_force_damping>
</drake:linear_bushing_rpy>
</model>
</sdf>