<?xml version='1.0'?>
<sdf xmlns:drake="http://drake.mit.edu" version="1.9">
<model name="digit">
<pose>0 0 0 0 0 0</pose>
    <include> 
        <uri>package://digit_sdf_model/digit_torso.sdf</uri>
        <pose>0 0 0 0 0 0</pose>
        <name>digit_torso</name>
    </include>
    <include>
        <uri>package://digit_sdf_model/digit_left_arm.sdf</uri>
        <pose relative_to="digit_torso">-0.001 0.12 0.4 0 -1.5708 0</pose>
        <name>digit_left_arm</name>
    </include>
    <include>
        <uri>package://digit_sdf_model/digit_right_arm.sdf</uri>
        <pose relative_to="digit_torso">-0.001 -0.12 0.4 0 -1.5708 0</pose>
        <name>digit_right_arm</name>
    </include>
    <include>
        <uri>package://digit_sdf_model/digit_left_leg.sdf</uri>
        <pose relative_to="digit_torso">-0.001 0.091 0 0 -1.5708 0</pose>
        <name>digit_left_leg</name>
    </include>
    <include>
        <uri>package://digit_sdf_model/digit_right_leg.sdf</uri>
        <pose relative_to="digit_torso">-0.001 -0.091 0 0 -1.5708 0</pose>
        <name>digit_right_leg</name>
    </include>
    <joint name="shoulder_roll_joint_left" type="continuous">
        <pose relative_to="digit_left_arm">0 0 0 0 0 0</pose>
        <axis>
            <xyz>0 0 1</xyz>
            <limit>
                <lower>-1.309</lower>
                <upper>1.309</upper>
                <effort>1.4</effort>
                <velocity>12.5</velocity>
            </limit>
            <dynamics>
                <damping>2</damping>
                <friction>2</friction>
            </dynamics>
        </axis>
        <parent>digit_torso::torso</parent>
        <child>digit_left_arm::left_shoulder_roll</child>
        <drake:gear_ratio>80</drake:gear_ratio>
        <drake:rotor_inertia>0.173824</drake:rotor_inertia>
    </joint>
    <joint name="shoulder_roll_joint_right" type="continuous">
        <pose relative_to="digit_right_arm">0 0 0 0 0 0</pose>
        <axis>
            <xyz>0 0 1</xyz>
            <limit>
                <lower>-1.309</lower>
                <upper>1.309</upper>
                <effort>1.4</effort>
                <velocity>12.5</velocity>
            </limit>
            <dynamics>
                <damping>2</damping>
                <friction>2</friction>
            </dynamics>
        </axis>
        <parent>digit_torso::torso</parent>
        <child>digit_right_arm::right_shoulder_roll</child>
        <drake:gear_ratio>80</drake:gear_ratio>
        <drake:rotor_inertia>0.173824</drake:rotor_inertia>
    </joint>
    <joint name="left_hip_roll" type="continuous">
        <pose relative_to="digit_left_leg">0 0 0 0 0 0</pose>
        <axis>
            <xyz>0 0 1</xyz>
            <limit>
                <lower>-1.0472</lower>
                <upper>1.0472</upper>
                <effort>1.4</effort>
                <velocity>12.5</velocity>
            </limit>
            <dynamics>
                <damping>1</damping>
                <friction>1</friction>
            </dynamics>
        </axis>
        <parent>digit_torso::torso</parent>
        <child>digit_left_leg::left_hip_roll</child>
        <drake:gear_ratio>80</drake:gear_ratio>
        <drake:rotor_inertia>0.173824</drake:rotor_inertia>
    </joint>
    <joint name="right_hip_roll" type="continuous">
        <pose relative_to="digit_right_leg">0 0 0 0 0 0</pose>
        <axis>
            <xyz>0 0 1</xyz>
            <limit>
                <lower>-1.0472</lower>
                <upper>1.0472</upper>
                <effort>1.4</effort>
                <velocity>12.5</velocity>
            </limit>
            <dynamics>
                <damping>1</damping>
                <friction>1</friction>
            </dynamics>
        </axis>
        <parent>digit_torso::torso</parent>
        <child>digit_right_leg::right_hip_roll</child>
        <drake:gear_ratio>80</drake:gear_ratio>
        <drake:rotor_inertia>0.173824</drake:rotor_inertia>
    </joint>
</model>
</sdf>